<robot name="three_link_planar_capsule">
  <link name="base_link" />

  <link name="mounting_link">
    <visual>
      <geometry>
        <box size="0.03 0.03 0.03" />
      </geometry>
      <material name="black">
        <color rgba="0 0 0 1"/>
      </material>
    </visual>
  </link>


  <link name="link1">
    <visual>
      <geometry>
        <cylinder length="0.196" radius="0.015"/>
      </geometry>
      <origin rpy="1.57 0 0" xyz="0 -0.098 0"/>
      <material name="grey1">
        <color rgba="0.4 0.4 0.4 1"/>
      </material>
    </visual>
    <collision>
      <geometry>
        <cylinder length="0.196" radius="0.015"/>
      </geometry>
      <origin rpy="1.57 0 0" xyz="0 -0.098 0"/>
    </collision>

    <visual>
      <geometry>
        <sphere radius="0.015"/>
      </geometry>
      <origin rpy="0 0 0" xyz="0 0 0"/>
      <material name="grey1">
        <color rgba="0.4 0.4 0.4 1"/>
      </material>
    </visual>
    <collision>
      <geometry>
        <sphere radius="0.015"/>
      </geometry>
      <origin rpy="0 0 0" xyz="0 0 0"/>
    </collision>

    <visual>
      <geometry>
        <sphere radius="0.015"/>
      </geometry>
      <origin rpy="0 0 0" xyz="0 -0.196 0"/>
      <material name="grey1">
        <color rgba="0.4 0.4 0.4 1"/>
      </material>
    </visual>
    <collision>
      <geometry>
        <sphere radius="0.015"/>
      </geometry>
      <origin rpy="0 0 0" xyz="0 -0.196 0"/>
    </collision>

    <inertial>
      <mass value="2.835"/>
      <inertia ixx="1.0" ixy="0.0" ixz="0.0" iyy="0.0" iyz="0.0" izz="0.0"/>
    </inertial>
  </link>

  <link name="link2">
    <visual>
      <geometry>
        <cylinder length="0.334" radius="0.015"/>
      </geometry>
      <origin rpy="1.57 0 0" xyz="0 -0.167 0"/>
      <material name="grey2">
        <color rgba="0.8 0.8 0.8 1"/>
      </material>
    </visual>
    <collision>
      <geometry>
        <cylinder length="0.334" radius="0.015"/>
      </geometry>
      <origin rpy="1.57 0 0" xyz="0 -0.167 0"/>
    </collision>

    <visual>
      <geometry>
        <sphere radius="0.015"/>
      </geometry>
      <origin rpy="0 0 0" xyz="0 0 0"/>
      <material name="grey2">
        <color rgba="0.8 0.8 0.8 1"/>
      </material>
    </visual>
    <collision>
      <geometry>
        <sphere radius="0.015"/>
      </geometry>
      <origin rpy="0 0 0" xyz="0 0 0"/>
    </collision>

    <visual>
      <geometry>
        <sphere radius="0.015"/>
      </geometry>
      <origin rpy="0 0 0" xyz="0 -0.334 0"/>
      <material name="grey2">
        <color rgba="0.8 0.8 0.8 1"/>
      </material>
    </visual>
    <collision>
      <geometry>
        <sphere radius="0.015"/>
      </geometry>
      <origin rpy="0 0 0" xyz="0 -0.334 0"/>
    </collision>

    <inertial>
      <mass value="2.3"/>
      <inertia ixx="1.0" ixy="0.0" ixz="0.0" iyy="0.0" iyz="0.0" izz="0.0"/>
    </inertial>
  </link>

  <link name="link3">
    <visual>
      <geometry>
        <cylinder length="0.273" radius="0.015"/>
      </geometry>
      <origin rpy="1.57 0 0" xyz="0 -0.1365 0"/>
      <material name="grey3">
        <color rgba="0.33 0.33 0.33 1"/>
      </material>
    </visual>
    <collision>
      <geometry>
        <cylinder length="0.273" radius="0.015"/>
      </geometry>
      <origin rpy="1.57 0 0" xyz="0 -0.1365 0"/>
    </collision>

    <visual>
      <geometry>
        <sphere radius="0.015"/>
      </geometry>
      <origin rpy="0 0 0" xyz="0 0.0 0"/>
      <material name="grey3">
        <color rgba="0.33 0.33 0.33 1"/>
      </material>
    </visual>
    <collision>
      <geometry>
        <sphere radius="0.015"/>
      </geometry>
      <origin rpy="0 0 0" xyz="0 0 0"/>
    </collision>

    <visual>
      <geometry>
        <sphere radius="0.015"/>
      </geometry>
      <origin rpy="0 0 0" xyz="0 -0.273 0"/>
      <material name="grey3">
        <color rgba="0.33 0.33 0.33 1"/>
      </material>
    </visual>
    <collision>
      <geometry>
        <sphere radius="0.015"/>
      </geometry>
      <origin rpy="0 0 0" xyz="0 -0.273 0"/>
    </collision>

    <inertial>
      <mass value="1.32"/>
      <inertia ixx="1.0" ixy="0.0" ixz="0.0" iyy="0.0" iyz="0.0" izz="0.0"/>
    </inertial>
  </link>

  <link name="tool_link">
  </link>

  <joint name="mounting_joint" type="fixed">
    <parent link="base_link"/>
    <child link="mounting_link"/>
    <origin xyz="0 0 0" rpy="0 0 1.57" />
    <axis xyz="0 0 1" />
  </joint>

  <joint name="joint1" type="revolute">
    <parent link="mounting_link"/>
    <child link="link1"/>
    <origin xyz="0 0 0" rpy="0 0 -1.57" />
    <axis xyz="0 0 1" />
    <limit effort="18" lower="-2.62" upper="2.62" velocity="2"/>
  </joint>

  <joint name="joint2" type="revolute">
    <parent link="link1"/>
    <child link="link2"/>
    <origin xyz="0 -0.196 0" rpy="0 0 0" />
    <axis xyz="0 0 1" />
    <limit effort="18" lower="-1.1" upper="2.83" velocity="2"/>
  </joint>

  <joint name="joint3" type="revolute">
    <parent link="link2"/>
    <child link="link3"/>
    <origin xyz="0 -0.334 0" rpy="0 0 0" />
    <axis xyz="0 0 1" />
    <limit effort="18" lower="0.0" upper="2.78" velocity="2"/>
  </joint>

  <joint name="tool_joint" type="fixed">
    <parent link="link3"/>
    <child link="tool_link"/>
    <origin xyz="0 -0.288 0" rpy="0 0 0" />
    <axis xyz="0 0 1" />
  </joint>

</robot>