<?xml version="1.0"?>
<sdf version="1.4">
  <model name="simple_prismatic_robot_leglift_2">
    <static>false</static>
    <link name="base_link">
      <pose>0 0 0.45 0 0 0</pose>-->
      <!--<pose>0 0 0.46 0 0 0</pose>-->
      <inertial>
        <mass>100000000.</mass>
        <inertia>
          <ixx>100000000.</ixx>
          <ixy>0</ixy>
          <ixz>0</ixz>
          <iyy>100000000.</iyy>
          <iyz>0</iyz>
          <izz>100000000.</izz>
        </inertia>
      </inertial>
      <collision name='collision'>
        <geometry>
          <box>
            <size>2. 0.2 0.9</size>-->
            <!--<size>2. 0.2 0.92</size>-->
            <!--<size>1. 0.2 0.01</size>-->
          </box>
        </geometry>
      </collision>
      <!--<visual name='visual'>
        <geometry>
          <box>
            <size>2. 0.2 0.9</size>-->
            <!--<size>2. 0.2 0.92</size>-->
            <!--<size>1. 0.2 0.01</size>-->
          <!--</box>
        </geometry>
      </visual>-->
      <gravity>0</gravity>
    </link>
    <link name="robot_arm_y">
      <pose>0 0 0.9 0 0 0</pose>-->
      <!--<pose>0 0 0.92 0 0 0</pose>-->
      <!--<pose>0 0 0.88 0 0 0</pose>-->
      <inertial>
        <mass>1.</mass>
        <inertia>
          <ixx>1.</ixx>
          <ixy>0</ixy>
          <ixz>0</ixz>
          <iyy>1.</iyy>
          <iyz>0</iyz>
          <izz>1.</izz>
        </inertia>
      </inertial>
      <!--<collision name='collision'>
        <geometry>
          <box>
            <size>2 2 0.5</size>
          </box>
        </geometry>
      </collision>-->
      <visual name='visual'>
        <geometry>
          <box>
            <size>0.1 0.1 0.1</size>
          </box>
        </geometry>
      </visual>-->
      <gravity>0</gravity>
    </link>
    <link name="robot_arm_z">
      <pose>0 0 0.9 0 0 0</pose>-->
      <!--<pose>0 0 0.92 0 0 0</pose>-->
      <!--<pose>0 0 0.88 0 0 0</pose>-->
      <inertial>
        <mass>1.</mass>
        <inertia>
          <ixx>1.</ixx>
          <ixy>0</ixy>
          <ixz>0</ixz>
          <iyy>1.</iyy>
          <iyz>0</iyz>
          <izz>1.</izz>
        </inertia>
      </inertial>
      <!--<collision name='collision'>
        <geometry>
          <box>
            <size>2 2 0.5</size>
          </box>
        </geometry>
      </collision>-->
      <visual name='visual'>
        <geometry>
          <box>
            <size>0.1 0.1 0.1</size>
          </box>
        </geometry>
      </visual>-->
      <gravity>0</gravity>
    </link>
    <link name="revolute_link">
      <!--<pose>0. 0 0.9205 0 0 0</pose>-->
      <pose>0. 0 0.9 0 0 0</pose>-->
      <!--<pose>0. 0 0.8805 0 0 0</pose>-->
      <inertial>
        <pose>0. 0 0 0 0 0</pose>
        <mass>1.</mass>
        <inertia>
          <ixx>0.1</ixx>
          <ixy>0</ixy>
          <ixz>0</ixz>
          <iyy>0.1</iyy>
          <iyz>0</iyz>
          <izz>0.1</izz>
        </inertia>
      </inertial>
      <collision name='collision'>
        <pose>0. 0 0 0 0 0</pose>
        <geometry>
          <box>
            <!--<size>0.1 0.2 0.01</size>-->
            <!--<size>0.15 0.104 0.05</size>-->
            <size>0.15 0.104 0.01</size>
          </box>
        </geometry>
        <surface>
          <friction>
            <ode>
              <mu>0.500000</mu>
              <mu2>0.500000</mu2>-->
              <!--<mu>0.15000</mu>
              <mu2>0.15000</mu2>-->
            </ode>
          </friction>
        </surface>
      </collision>
      <visual name='visual'>
        <pose>0. 0 0 0 0 0</pose>
        <geometry>
          <box>
            <!--<size>0.1 0.2 0.01</size>-->
            <!--<size>0.15 0.104 0.05</size>-->
            <size>0.15 0.104 0.01</size>
          </box>
        </geometry>
      </visual>
      <gravity>0</gravity>
    </link>
    <link name="robot_arm_y_2">
      <!--<pose>0 -0.4 0.92 0 0 0</pose>-->
      <!--<pose>0 -0.4 0.88 0 0 0</pose>-->
      <!--<pose>0 -0.425 0.92 0 0 0</pose>-->
      <pose>0 -0.425 0.9 0 0 0</pose>-->
      <inertial>
        <mass>1.</mass>
        <inertia>
          <ixx>1.</ixx>
          <ixy>0</ixy>
          <ixz>0</ixz>
          <iyy>1.</iyy>
          <iyz>0</iyz>
          <izz>1.</izz>
        </inertia>
      </inertial>
      <!--<collision name='collision'>
        <geometry>
          <box>
            <size>2 2 0.5</size>
          </box>
        </geometry>
      </collision>-->
      <visual name='visual'>
        <geometry>
          <box>
            <size>0.1 0.1 0.1</size>
          </box>
        </geometry>
      </visual>-->
      <gravity>0</gravity>
    </link>
    <link name="robot_arm_z_2">
      <!--<pose>0 -0.4 0.92 0 0 0</pose>-->
      <!--<pose>0 -0.4 0.88 0 0 0</pose>-->
      <!--<pose>0 -0.425 0.92 0 0 0</pose>-->
      <pose>0 -0.425 0.9 0 0 0</pose>-->
      <inertial>
        <mass>1.</mass>
        <inertia>
          <ixx>1.</ixx>
          <ixy>0</ixy>
          <ixz>0</ixz>
          <iyy>1.</iyy>
          <iyz>0</iyz>
          <izz>1.</izz>
        </inertia>
      </inertial>
      <!--<collision name='collision'>
        <geometry>
          <box>
            <size>2 2 0.5</size>
          </box>
        </geometry>
      </collision>-->
      <visual name='visual'>
        <geometry>
          <box>
            <size>0.1 0.1 0.1</size>
          </box>
        </geometry>
      </visual>-->
      <gravity>0</gravity>
    </link>
    <link name="revolute_link_2">
      <!--<pose>0. -0.4 0.9205 0 0 0</pose>-->
      <!--<pose>0. -0.4 0.8805 0 0 0</pose>-->
      <!--<pose>0. -0.425 0.9205 0 0 0</pose>-->
      <pose>0. -0.425 0.9 0 0 0</pose>-->
      <inertial>
        <pose>0. 0 0 0 0 0</pose>
        <mass>1.</mass>
        <inertia>
          <ixx>0.1</ixx>
          <ixy>0</ixy>
          <ixz>0</ixz>
          <iyy>0.1</iyy>
          <iyz>0</iyz>
          <izz>0.1</izz>
        </inertia>
      </inertial>
      <collision name='collision'>
        <pose>0. 0 0 0 0 0</pose>
        <geometry>
          <box>
            <!--<size>0.1 0.2 0.01</size>-->
            <!--<size>0.15 0.104 0.05</size>-->
            <size>0.15 0.104 0.01</size>
          </box>
        </geometry>
        <surface>
          <friction>
            <ode>
              <mu>0.500000</mu>
              <mu2>0.500000</mu2>-->
              <!--<mu>0.15000</mu>
              <mu2>0.15000</mu2>-->
            </ode>
          </friction>
        </surface>
      </collision>
      <visual name='visual'>
        <pose>0. 0 0 0 0 0</pose>
        <geometry>
          <box>
            <!--<size>0.1 0.2 0.01</size>-->
            <!--<size>0.15 0.104 0.05</size>-->
            <size>0.15 0.104 0.01</size>
          </box>
        </geometry>
      </visual>
      <gravity>0</gravity>
    </link>
    <joint name="revolute_joint" type="revolute">
      <parent>robot_arm_z</parent>
      <child>revolute_link</child>
      <axis>
        <xyz>1 0 0</xyz>
        <limit>
          <!--<lower>-1.57</lower>
          <upper>0.</upper>-->
          <!--<lower>-0.707</lower>
          <upper>0.707</upper>-->
          <lower>-1000</lower>
          <upper>1000</upper>
        </limit>
      </axis>
      <physics>
        <ode>
          <provide_feedback>True</provide_feedback>
        </ode>
      </physics>-->
    </joint>
    <joint name="robot_joint_y" type="prismatic">
      <parent>base_link</parent>
      <child>robot_arm_y</child>
      <axis>
        <xyz>0 1 0</xyz>
        <limit>
          <!--<lower>-0.25</lower>
          <upper>0.5</upper>-->
          <lower>-1.</lower>
          <upper>1.</upper>
        </limit>
      </axis>
      <physics>
        <ode>
          <provide_feedback>True</provide_feedback>
        </ode>
      </physics>-->
    </joint>
    <joint name="robot_joint_z" type="prismatic">
      <parent>robot_arm_y</parent>
      <child>robot_arm_z</child>
      <axis>
        <xyz>0 0 1.0</xyz>
        <limit>
          <lower>0.</lower>
          <!--<upper>0.5</upper>-->
          <upper>1.</upper>
        </limit>
      </axis>
      <physics>
        <ode>
          <provide_feedback>True</provide_feedback>
        </ode>
      </physics>-->
    </joint>
    <joint name="revolute_joint_2" type="revolute">
      <parent>robot_arm_z_2</parent>
      <child>revolute_link_2</child>
      <axis>
        <xyz>1 0 0</xyz>
        <limit>
          <!--<lower>-1.57</lower>
          <upper>0.</upper>-->
          <!--<lower>-0.707</lower>
          <upper>0.707</upper>-->
          <lower>-1000</lower>
          <upper>1000</upper>
        </limit>
      </axis>
      <physics>
        <ode>
          <provide_feedback>True</provide_feedback>
        </ode>
      </physics>-->
    </joint>
    <joint name="robot_joint_y_2" type="prismatic">
      <parent>base_link</parent>
      <child>robot_arm_y_2</child>
      <axis>
        <xyz>0 1 0</xyz>
        <limit>
          <!--<lower>-0.25</lower>
          <upper>0.5</upper>-->
          <lower>-1.</lower>
          <upper>1.</upper>
        </limit>
      </axis>
      <physics>
        <ode>
          <provide_feedback>True</provide_feedback>
        </ode>
      </physics>-->
    </joint>
    <joint name="robot_joint_z_2" type="prismatic">
      <parent>robot_arm_y_2</parent>
      <child>robot_arm_z_2</child>
      <axis>
        <xyz>0 0 1.0</xyz>
        <limit>
          <lower>0.</lower>
          <!--<upper>0.5</upper>-->
          <upper>1.</upper>
        </limit>
      </axis>
      <physics>
        <ode>
          <provide_feedback>True</provide_feedback>
        </ode>
      </physics>-->
    </joint>
    <plugin name="ros_model_plugin" filename="libros_model_plugin.so" />-->
  </model>
</sdf>
